Workbook

Sheet theory
A1: BLACK | B1: black | C1: 0 | D1: =DEC2HEX(C1,2) -> 00 | E1: 64 | G1: =_xlfn.CONCAT("""",A1,""" : ", C1," ,") -> "BLACK" : 0 ,
A2: GREEN | B2: lime | C2: 1 | D2: =DEC2HEX(C2,2) -> 01 | E2: 15 | G2: =_xlfn.CONCAT("""",A2,""" : ", C2," ,") -> "GREEN" : 1 ,
A3: BLUE | B3: blue | C3: 2 | D3: =DEC2HEX(C3,2) -> 02 | E3: 16 | G3: =_xlfn.CONCAT("""",A3,""" : ", C3," ,") -> "BLUE" : 2 ,
A4: PURPLE | B4: purple | C4: 3 | D4: =DEC2HEX(C4,2) -> 03 | E4: 17 | G4: =_xlfn.CONCAT("""",A4,""" : ", C4," ,") -> "PURPLE" : 3 ,
A5: YELLOW | B5: yellow | C5: 4 | D5: =DEC2HEX(C5,2) -> 04 | E5: 18 | G5: =_xlfn.CONCAT("""",A5,""" : ", C5," ,") -> "YELLOW" : 4 ,
A6: PINK | B6: orchid | C6: 5 | D6: =DEC2HEX(C6,2) -> 05 | E6: 19 | G6: =_xlfn.CONCAT("""",A6,""" : ", C6," ,") -> "PINK" : 5 ,
A7: GRAY | B7: grey | C7: 6 | D7: =DEC2HEX(C7,2) -> 06 | E7: 20 | G7: =_xlfn.CONCAT("""",A7,""" : ", C7," ,") -> "GRAY" : 6 ,
A8: WHITE | B8: white | C8: 7 | D8: =DEC2HEX(C8,2) -> 07 | E8: 21 | G8: =_xlfn.CONCAT("""",A8,""" : ", C8," ,") -> "WHITE" : 7 ,
A9: ORANGE | B9: orange | C9: 8 | D9: =DEC2HEX(C9,2) -> 08 | E9: 22 | G9: =_xlfn.CONCAT("""",A9,""" : ", C9," ,") -> "ORANGE" : 8 ,
A10: RED | B10: red | C10: 9 | D10: =DEC2HEX(C10,2) -> 09 | E10: 23 | G10: =_xlfn.CONCAT("""",A10,""" : ", C10," ,") -> "RED" : 9 ,
A11: LIGHT BLUE | B11: skyblue | C11: 10 | D11: =DEC2HEX(C11,2) -> 0A | E11: 24 | G11: =_xlfn.CONCAT("""",A11,""" : ", C11," ,") -> "LIGHT BLUE" : 10 ,
A12: DARK PINK | B12: deeppink | C12: 11 | D12: =DEC2HEX(C12,2) -> 0B | E12: 25 | G12: =_xlfn.CONCAT("""",A12,""" : ", C12," ,") -> "DARK PINK" : 11 ,
... A50: LIGHT GRAY | B50: lightgray | C50: 63 | D50: =DEC2HEX(C50,2) -> 3F | E50: 127 | G50: =_xlfn.CONCAT("""",A50,""" : ", C50," ,") -> "LIGHT GRAY" : 63 ,

Sheet practice
D1: sysex | E1: hatch
C2: Picker place | D2: code | E2: sysex
A3: indianred | B3: #cd5c5c | C3: 0 | D3: =VLOOKUP($A3,theory!$B$1:$C$50,2,FALSE) -> 55 | E3: =VLOOKUP($A3,theory!$B$1:$E$50,4,FALSE) -> 119 | G3: =_xlfn.CONCAT("""",B3,""" : ", C3," ,") -> "#cd5c5c" : 0 , | J3: =_xlfn.CONCAT(B3," : ", C3, " ,") -> #cd5c5c : 0 , | L3: =_xlfn.CONCAT("""",A3,""",") -> "indianred", | N3: =LEN(B3) -> 7 | Q3: =_xlfn.CONCAT("""",B3,""", ") -> "#cd5c5c", | S3: =_xlfn.CONCAT("""",A3,""" : ", C3," ,") -> "indianred" : 0 ,
A4: salmon | B4: #fa8072 | C4: 1 | D4: =VLOOKUP($A4,theory!$B$1:$C$50,2,FALSE) -> 56 | E4: =VLOOKUP($A4,theory!$B$1:$E$50,4,FALSE) -> 120 | G4: =_xlfn.CONCAT("""",B4,""" : ", C4," ,") -> "#fa8072" : 1 , | J4: =_xlfn.CONCAT(B4," : ", C4, " ,") -> #fa8072 : 1 , | L4: =_xlfn.CONCAT("""",A4,""",") -> "salmon", | N4: =LEN(B4) -> 7 | Q4: =_xlfn.CONCAT("""",B4,""", ") -> "#fa8072", | S4: =_xlfn.CONCAT("""",A4,""" : ", C4," ,") -> "salmon" : 1 ,
A5: red | B5: #ff0000 | C5: 2 | D5: =VLOOKUP($A5,theory!$B$1:$C$50,2,FALSE) -> 9 | E5: =VLOOKUP($A5,theory!$B$1:$E$50,4,FALSE) -> 23 | G5: =_xlfn.CONCAT("""",B5,""" : ", C5," ,") -> "#ff0000" : 2 , | J5: =_xlfn.CONCAT(B5," : ", C5, " ,") -> #ff0000 : 2 , | L5: =_xlfn.CONCAT("""",A5,""",") -> "red", | N5: =LEN(B5) -> 7 | Q5: =_xlfn.CONCAT("""",B5,""", ") -> "#ff0000", | S5: =_xlfn.CONCAT("""",A5,""" : ", C5," ,") -> "red" : 2 ,
A6: firebrick | B6: #b22222 | C6: 3 | D6: =VLOOKUP($A6,theory!$B$1:$C$50,2,FALSE) -> 57 | E6: =VLOOKUP($A6,theory!$B$1:$E$50,4,FALSE) -> 121 | G6: =_xlfn.CONCAT("""",B6,""" : ", C6," ,") -> "#b22222" : 3 , | J6: =_xlfn.CONCAT(B6," : ", C6, " ,") -> #b22222 : 3 , | L6: =_xlfn.CONCAT("""",A6,""",") -> "firebrick", | N6: =LEN(B6) -> 7 | Q6: =_xlfn.CONCAT("""",B6,""", ") -> "#b22222", | S6: =_xlfn.CONCAT("""",A6,""" : ", C6," ,") -> "firebrick" : 3 ,
A7: darkred | B7: #8b0000 | C7: 4 | D7: =VLOOKUP($A7,theory!$B$1:$C$50,2,FALSE) -> 58 | E7: =VLOOKUP($A7,theory!$B$1:$E$50,4,FALSE) -> 122 | G7: =_xlfn.CONCAT("""",B7,""" : ", C7," ,") -> "#8b0000" : 4 , | J7: =_xlfn.CONCAT(B7," : ", C7, " ,") -> #8b0000 : 4 , | L7: =_xlfn.CONCAT("""",A7,""",") -> "darkred", | N7: =LEN(B7) -> 7 | Q7: =_xlfn.CONCAT("""",B7,""", ") -> "#8b0000", | S7: =_xlfn.CONCAT("""",A7,""" : ", C7," ,") -> "darkred" : 4 ,
A8: lightpink | B8: #ffb6c1 | C8: 5 | D8: =VLOOKUP($A8,theory!$B$1:$C$50,2,FALSE) -> 59 | E8: =VLOOKUP($A8,theory!$B$1:$E$50,4,FALSE) -> 123 | G8: =_xlfn.CONCAT("""",B8,""" : ", C8," ,") -> "#ffb6c1" : 5 , | J8: =_xlfn.CONCAT(B8," : ", C8, " ,") -> #ffb6c1 : 5 , | L8: =_xlfn.CONCAT("""",A8,""",") -> "lightpink", | N8: =LEN(B8) -> 7 | Q8: =_xlfn.CONCAT("""",B8,""", ") -> "#ffb6c1", | S8: =_xlfn.CONCAT("""",A8,""" : ", C8," ,") -> "lightpink" : 5 ,
A9: hotpink | B9: #ff69b4 | C9: 6 | D9: =VLOOKUP($A9,theory!$B$1:$C$50,2,FALSE) -> 60 | E9: =VLOOKUP($A9,theory!$B$1:$E$50,4,FALSE) -> 124 | G9: =_xlfn.CONCAT("""",B9,""" : ", C9," ,") -> "#ff69b4" : 6 , | J9: =_xlfn.CONCAT(B9," : ", C9, " ,") -> #ff69b4 : 6 , | L9: =_xlfn.CONCAT("""",A9,""",") -> "hotpink", | N9: =LEN(B9) -> 7 | Q9: =_xlfn.CONCAT("""",B9,""", ") -> "#ff69b4", | S9: =_xlfn.CONCAT("""",A9,""" : ", C9," ,") -> "hotpink" : 6 ,
A10: deeppink | B10: #ff1493 | C10: 7 | D10: =VLOOKUP($A10,theory!$B$1:$C$50,2,FALSE) -> 11 | E10: =VLOOKUP($A10,theory!$B$1:$E$50,4,FALSE) -> 25 | G10: =_xlfn.CONCAT("""",B10,""" : ", C10," ,") -> "#ff1493" : 7 , | J10: =_xlfn.CONCAT(B10," : ", C10, " ,") -> #ff1493 : 7 , | L10: =_xlfn.CONCAT("""",A10,""",") -> "deeppink", | N10: =LEN(B10) -> 7 | Q10: =_xlfn.CONCAT("""",B10,""", ") -> "#ff1493", | S10: =_xlfn.CONCAT("""",A10,""" : ", C10," ,") -> "deeppink" : 7 ,
A11: palevioletred | B11: #db7093 | C11: 8 | D11: =VLOOKUP($A11,theory!$B$1:$C$50,2,FALSE) -> 61 | E11: =VLOOKUP($A11,theory!$B$1:$E$50,4,FALSE) -> 125 | G11: =_xlfn.CONCAT("""",B11,""" : ", C11," ,") -> "#db7093" : 8 , | J11: =_xlfn.CONCAT(B11," : ", C11, " ,") -> #db7093 : 8 , | L11: =_xlfn.CONCAT("""",A11,""",") -> "palevioletred", | N11: =LEN(B11) -> 7 | Q11: =_xlfn.CONCAT("""",B11,""", ") -> "#db7093", | S11: =_xlfn.CONCAT("""",A11,""" : ", C11," ,") -> "palevioletred" : 8 ,
A12: lightsalmon | B12: #ffa07a | C12: 9 | D12: =VLOOKUP($A12,theory!$B$1:$C$50,2,FALSE) -> 51 | E12: =VLOOKUP($A12,theory!$B$1:$E$50,4,FALSE) -> 115 | G12: =_xlfn.CONCAT("""",B12,""" : ", C12," ,") -> "#ffa07a" : 9 , | J12: =_xlfn.CONCAT(B12," : ", C12, " ,") -> #ffa07a : 9 , | L12: =_xlfn.CONCAT("""",A12,""",") -> "lightsalmon", | N12: =LEN(B12) -> 7 | Q12: =_xlfn.CONCAT("""",B12,""", ") -> "#ffa07a", | S12: =_xlfn.CONCAT("""",A12,""" : ", C12," ,") -> "lightsalmon" : 9 ,
A13: tomato | B13: #ff6347 | C13: 10 | D13: =VLOOKUP($A13,theory!$B$1:$C$50,2,FALSE) -> 52 | E13: =VLOOKUP($A13,theory!$B$1:$E$50,4,FALSE) -> 116 | G13: =_xlfn.CONCAT("""",B13,""" : ", C13," ,") -> "#ff6347" : 10 , | J13: =_xlfn.CONCAT(B13," : ", C13, " ,") -> #ff6347 : 10 , | L13: =_xlfn.CONCAT("""",A13,""",") -> "tomato", | N13: =LEN(B13) -> 7 | Q13: =_xlfn.CONCAT("""",B13,""", ") -> "#ff6347", | S13: =_xlfn.CONCAT("""",A13,""" : ", C13," ,") -> "tomato" : 10 ,
A14: orangered | B14: #ff4500 | C14: 11 | D14: =VLOOKUP($A14,theory!$B$1:$C$50,2,FALSE) -> 53 | E14: =VLOOKUP($A14,theory!$B$1:$E$50,4,FALSE) -> 117 | G14: =_xlfn.CONCAT("""",B14,""" : ", C14," ,") -> "#ff4500" : 11 , | J14: =_xlfn.CONCAT(B14," : ", C14, " ,") -> #ff4500 : 11 , | L14: =_xlfn.CONCAT("""",A14,""",") -> "orangered", | N14: =LEN(B14) -> 7 | Q14: =_xlfn.CONCAT("""",B14,""", ") -> "#ff4500", | S14: =_xlfn.CONCAT("""",A14,""" : ", C14," ,") -> "orangered" : 11 ,
... A52: black | B52: #000000 | C52: 49 | D52: =VLOOKUP($A52,theory!$B$1:$C$50,2,FALSE) -> 0 | E52: =VLOOKUP($A52,theory!$B$1:$E$50,4,FALSE) -> 64 | G52: =_xlfn.CONCAT("""",B52,""" : ", C52," ,") -> "#000000" : 49 , | J52: =_xlfn.CONCAT(B52," : ", C52, " ,") -> #000000 : 49 , | L52: =_xlfn.CONCAT("""",A52,""",") -> "black", | N52: =LEN(B52) -> 7 | Q52: =_xlfn.CONCAT("""",B52,""", ") -> "#000000", | S52: =_xlfn.CONCAT("""",A52,""" : ", C52," ,") -> "black" : 49 ,

Sheet Sheet3
A1: 0000 f0 00 21 24 09 00 06 11 00 0e 00 00 00 00 00 00 | F1: =_xlfn.CONCAT("""",RIGHT(A1,LEN(A1)-7),"""") -> "f0 00 21 24 09 00 06 11 00 0e 00 00 00 00 00 00" | G1: f000212409000611000e0000000000007f0003010e007f01170024072c2f0101020000000000000000000000000000007f011701240708070102020000000000000000000000000000007f011702240700070103020000000000000000000000000000007f0117030e0300000107020000000000000000000000000000007f0117040e0400000108020000000000000000000000000000007f011705000000000100020000000000000000000000000000007f011706000000000100020000000000000000000000000000007f011707000000000100020000000000000000000000000000007f011708000000000100020000000000000000000000000000007f011709000000000100020000000000000000000000000000007f01170a000000000100020000000000000000000000000000007f01170b000000000100020000000000000000000000000000007f01170c000000000100020000000000000000000000000000007f01170d000000000100020000000000000000000000000000007f01170e000000000100020000000000000000000000000000007f01170f000000000100020000000000000000000000000000007f011710000000000100020000000000000000000000000000007f011711000000000100020000000000000000000000000000007f011712000000000100020000000000000000000000000000007f011713000000000100020000000000000000000000000000007f011714000000000100020000000000000000000000000000007f011715000000000100020000000000000000000000000000007f011716000000000100020000000000000000000000000000007f011717000000000100020000000000000000000000000000007f011718000000000100020000000000000000000000000000007f011719000000000100020000000000000000000000000000007f01171a000000000100020000000000000000000000000000007f01171b000000000100020000000000000000000000000000007f01171c000000000100020000000000000000000000000000007f01171d000000000100020000000000000000000000000000007f01171e000000000100020000000000000000000000000000007f01171f000000000100020000000000000000000000000000007f0220454d5054592020202020202020202020202020202020202020202020202020207f032020202020202020202020202020202020202020202020202020202020202020207f042023232020202020202020202020202020202020202020202020202020202020207f0520000000000000000007070700000000000000000000000000000000000000007f062020202020202020202020202020202020202020202020202020202020202020201df7
A2: 0010 7f 00 03 01 0e 00 7f 01 17 00 24 07 2c 2f 01 01 | F2: =_xlfn.CONCAT("""",RIGHT(A2,LEN(A2)-7),"""") -> "7f 00 03 01 0e 00 7f 01 17 00 24 07 2c 2f 01 01" | G2: f000212409000611000e0000000000007f0003010e007f01170024072c2f0101020000000000000000000000000000007f011701240736070102020000000000000000000000000000007f011702240700070103020000000000000000000000000000007f0117030e0300000107020000000000000000000000000000007f0117040e0400000108020000000000000000000000000000007f011705000000000100020000000000000000000000000000007f011706000000000100020000000000000000000000000000007f011707000000000100020000000000000000000000000000007f011708000000000100020000000000000000000000000000007f011709000000000100020000000000000000000000000000007f01170a000000000100020000000000000000000000000000007f01170b000000000100020000000000000000000000000000007f01170c000000000100020000000000000000000000000000007f01170d000000000100020000000000000000000000000000007f01170e000000000100020000000000000000000000000000007f01170f000000000100020000000000000000000000000000007f011710000000000100020000000000000000000000000000007f011711000000000100020000000000000000000000000000007f011712000000000100020000000000000000000000000000007f011713000000000100020000000000000000000000000000007f011714000000000100020000000000000000000000000000007f011715000000000100020000000000000000000000000000007f011716000000000100020000000000000000000000000000007f011717000000000100020000000000000000000000000000007f011718000000000100020000000000000000000000000000007f011719000000000100020000000000000000000000000000007f01171a000000000100020000000000000000000000000000007f01171b000000000100020000000000000000000000000000007f01171c000000000100020000000000000000000000000000007f01171d000000000100020000000000000000000000000000007f01171e000000000100020000000000000000000000000000007f01171f000000000100020000000000000000000000000000007f0220454d5054592020202020202020202020202020202020202020202020202020207f032020202020202020202020202020202020202020202020202020202020202020207f042023232020202020202020202020202020202020202020202020202020202020207f0520000000000000000007070700000000000000000000000000000000000000007f0620202020202020202020202020202020202020202020202020202020202020202023f7
A3: 0020 02 00 00 00 00 00 00 00 00 00 00 00 00 00 00 00 | F3: =_xlfn.CONCAT("""",RIGHT(A3,LEN(A3)-7),"""") -> "02 00 00 00 00 00 00 00 00 00 00 00 00 00 00 00" | G3: f000212409000611000e0000000000007f0003010e007f01170024072c2f0101020000000000000000000000000000007f01170124072f070102020000000000000000000000000000007f011702240700070103020000000000000000000000000000007f0117030e0300000107020000000000000000000000000000007f0117040e0400000108020000000000000000000000000000007f011705000000000100020000000000000000000000000000007f011706000000000100020000000000000000000000000000007f011707000000000100020000000000000000000000000000007f011708000000000100020000000000000000000000000000007f011709000000000100020000000000000000000000000000007f01170a000000000100020000000000000000000000000000007f01170b000000000100020000000000000000000000000000007f01170c000000000100020000000000000000000000000000007f01170d000000000100020000000000000000000000000000007f01170e000000000100020000000000000000000000000000007f01170f000000000100020000000000000000000000000000007f011710000000000100020000000000000000000000000000007f011711000000000100020000000000000000000000000000007f011712000000000100020000000000000000000000000000007f011713000000000100020000000000000000000000000000007f011714000000000100020000000000000000000000000000007f011715000000000100020000000000000000000000000000007f011716000000000100020000000000000000000000000000007f011717000000000100020000000000000000000000000000007f011718000000000100020000000000000000000000000000007f011719000000000100020000000000000000000000000000007f01171a000000000100020000000000000000000000000000007f01171b000000000100020000000000000000000000000000007f01171c000000000100020000000000000000000000000000007f01171d000000000100020000000000000000000000000000007f01171e000000000100020000000000000000000000000000007f01171f000000000100020000000000000000000000000000007f0220454d5054592020202020202020202020202020202020202020202020202020207f032020202020202020202020202020202020202020202020202020202020202020207f042023232020202020202020202020202020202020202020202020202020202020207f0520000000000000000007070700000000000000000000000000000000000000007f062020202020202020202020202020202020202020202020202020202020202020203af7
A4: 0030 7f 01 17 01 24 07 36 07 01 02 02 00 00 00 00 00 | F4: =_xlfn.CONCAT("""",RIGHT(A4,LEN(A4)-7),"""") -> "7f 01 17 01 24 07 36 07 01 02 02 00 00 00 00 00"
A5: 0040 00 00 00 00 00 00 00 00 00 00 7f 01 17 02 24 07 | F5: =_xlfn.CONCAT("""",RIGHT(A5,LEN(A5)-7),"""") -> "00 00 00 00 00 00 00 00 00 00 7f 01 17 02 24 07" | G5: f000212409000611000e0000000000007f0003010e007f01170024070b2f0101020000000000000000000000000000007f011701240735070102020000000000000000000000000000007f011702240700070103020000000000000000000000000000007f0117030e0300000107020000000000000000000000000000007f0117040e0400000108020000000000000000000000000000007f011705000000000100020000000000000000000000000000007f011706000000000100020000000000000000000000000000007f011707000000000100020000000000000000000000000000007f011708000000000100020000000000000000000000000000007f011709000000000100020000000000000000000000000000007f01170a000000000100020000000000000000000000000000007f01170b000000000100020000000000000000000000000000007f01170c000000000100020000000000000000000000000000007f01170d000000000100020000000000000000000000000000007f01170e000000000100020000000000000000000000000000007f01170f000000000100020000000000000000000000000000007f011710000000000100020000000000000000000000000000007f011711000000000100020000000000000000000000000000007f011712000000000100020000000000000000000000000000007f011713000000000100020000000000000000000000000000007f011714000000000100020000000000000000000000000000007f011715000000000100020000000000000000000000000000007f011716000000000100020000000000000000000000000000007f011717000000000100020000000000000000000000000000007f011718000000000100020000000000000000000000000000007f011719000000000100020000000000000000000000000000007f01171a000000000100020000000000000000000000000000007f01171b000000000100020000000000000000000000000000007f01171c000000000100020000000000000000000000000000007f01171d000000000100020000000000000000000000000000007f01171e000000000100020000000000000000000000000000007f01171f000000000100020000000000000000000000000000007f0220454d5054592020202020202020202020202020202020202020202020202020207f032020202020202020202020202020202020202020202020202020202020202020207f042023232020202020202020202020202020202020202020202020202020202020207f0520000000000000000007070700000000000000000000000000000000000000007f0620202020202020202020202020202020202020202020202020202020202020202007f7
A6: 0050 00 07 01 03 02 00 00 00 00 00 00 00 00 00 00 00 | F6: =_xlfn.CONCAT("""",RIGHT(A6,LEN(A6)-7),"""") -> "00 07 01 03 02 00 00 00 00 00 00 00 00 00 00 00" | G6: f000212409000611000e0000000000007f0003010e007f0117002407052f0101020000000000000000000000000000007f01170124070d070102020000000000000000000000000000007f011702240700070103020000000000000000000000000000007f0117030e0300000107020000000000000000000000000000007f0117040e0400000108020000000000000000000000000000007f011705000000000100020000000000000000000000000000007f011706000000000100020000000000000000000000000000007f011707000000000100020000000000000000000000000000007f011708000000000100020000000000000000000000000000007f011709000000000100020000000000000000000000000000007f01170a000000000100020000000000000000000000000000007f01170b000000000100020000000000000000000000000000007f01170c000000000100020000000000000000000000000000007f01170d000000000100020000000000000000000000000000007f01170e000000000100020000000000000000000000000000007f01170f000000000100020000000000000000000000000000007f011710000000000100020000000000000000000000000000007f011711000000000100020000000000000000000000000000007f011712000000000100020000000000000000000000000000007f011713000000000100020000000000000000000000000000007f011714000000000100020000000000000000000000000000007f011715000000000100020000000000000000000000000000007f011716000000000100020000000000000000000000000000007f011717000000000100020000000000000000000000000000007f011718000000000100020000000000000000000000000000007f011719000000000100020000000000000000000000000000007f01171a000000000100020000000000000000000000000000007f01171b000000000100020000000000000000000000000000007f01171c000000000100020000000000000000000000000000007f01171d000000000100020000000000000000000000000000007f01171e000000000100020000000000000000000000000000007f01171f000000000100020000000000000000000000000000007f0220454d5054592020202020202020202020202020202020202020202020202020207f032020202020202020202020202020202020202020202020202020202020202020207f042023232020202020202020202020202020202020202020202020202020202020207f0520000000000000000007070700000000000000000000000000000000000000007f0620202020202020202020202020202020202020202020202020202020202020202031f7
A7: 0060 00 00 00 00 7f 01 17 03 0e 03 00 00 01 07 02 00 | F7: =_xlfn.CONCAT("""",RIGHT(A7,LEN(A7)-7),"""") -> "00 00 00 00 7f 01 17 03 0e 03 00 00 01 07 02 00" | G7: f000212409000611000e0000000000007f0003010e007f0117002407012f0101020000000000000000000000000000007f01170124070c070102020000000000000000000000000000007f011702240700070103020000000000000000000000000000007f0117030e0300000107020000000000000000000000000000007f0117040e0400000108020000000000000000000000000000007f011705000000000100020000000000000000000000000000007f011706000000000100020000000000000000000000000000007f011707000000000100020000000000000000000000000000007f011708000000000100020000000000000000000000000000007f011709000000000100020000000000000000000000000000007f01170a000000000100020000000000000000000000000000007f01170b000000000100020000000000000000000000000000007f01170c000000000100020000000000000000000000000000007f01170d000000000100020000000000000000000000000000007f01170e000000000100020000000000000000000000000000007f01170f000000000100020000000000000000000000000000007f011710000000000100020000000000000000000000000000007f011711000000000100020000000000000000000000000000007f011712000000000100020000000000000000000000000000007f011713000000000100020000000000000000000000000000007f011714000000000100020000000000000000000000000000007f011715000000000100020000000000000000000000000000007f011716000000000100020000000000000000000000000000007f011717000000000100020000000000000000000000000000007f011718000000000100020000000000000000000000000000007f011719000000000100020000000000000000000000000000007f01171a000000000100020000000000000000000000000000007f01171b000000000100020000000000000000000000000000007f01171c000000000100020000000000000000000000000000007f01171d000000000100020000000000000000000000000000007f01171e000000000100020000000000000000000000000000007f01171f000000000100020000000000000000000000000000007f0220454d5054592020202020202020202020202020202020202020202020202020207f032020202020202020202020202020202020202020202020202020202020202020207f042023232020202020202020202020202020202020202020202020202020202020207f0520000000000000000007070700000000000000000000000000000000000000007f0620202020202020202020202020202020202020202020202020202020202020202034f7
A8: 0070 00 00 00 00 00 00 00 00 00 00 00 00 00 00 7f 01 | F8: =_xlfn.CONCAT("""",RIGHT(A8,LEN(A8)-7),"""") -> "00 00 00 00 00 00 00 00 00 00 00 00 00 00 7f 01" | G8: f000212409000611000e0000000000007f0003010e007f01170024071e0a0101020000000000000000000000000000007f011701240706070102020000000000000000000000000000007f011702240700070103020000000000000000000000000000007f0117030e0300000107020000000000000000000000000000007f0117040e0400000108020000000000000000000000000000007f011705000000000100020000000000000000000000000000007f011706000000000100020000000000000000000000000000007f011707000000000100020000000000000000000000000000007f011708000000000100020000000000000000000000000000007f011709000000000100020000000000000000000000000000007f01170a000000000100020000000000000000000000000000007f01170b000000000100020000000000000000000000000000007f01170c000000000100020000000000000000000000000000007f01170d000000000100020000000000000000000000000000007f01170e000000000100020000000000000000000000000000007f01170f000000000100020000000000000000000000000000007f011710000000000100020000000000000000000000000000007f011711000000000100020000000000000000000000000000007f011712000000000100020000000000000000000000000000007f011713000000000100020000000000000000000000000000007f011714000000000100020000000000000000000000000000007f011715000000000100020000000000000000000000000000007f011716000000000100020000000000000000000000000000007f011717000000000100020000000000000000000000000000007f011718000000000100020000000000000000000000000000007f011719000000000100020000000000000000000000000000007f01171a000000000100020000000000000000000000000000007f01171b000000000100020000000000000000000000000000007f01171c000000000100020000000000000000000000000000007f01171d000000000100020000000000000000000000000000007f01171e000000000100020000000000000000000000000000007f01171f000000000100020000000000000000000000000000007f0220454d5054592020202020202020202020202020202020202020202020202020207f032020202020202020202020202020202020202020202020202020202020202020207f042023232020202020202020202020202020202020202020202020202020202020207f0520000000000000000007070700000000000000000000000000000000000000007f0620202020202020202020202020202020202020202020202020202020202020202004f7
A9: 0080 17 04 0e 04 00 00 01 08 02 00 00 00 00 00 00 00 | F9: =_xlfn.CONCAT("""",RIGHT(A9,LEN(A9)-7),"""") -> "17 04 0e 04 00 00 01 08 02 00 00 00 00 00 00 00"
A10: 0090 00 00 00 00 00 00 00 00 7f 01 17 05 00 00 00 00 | F10: =_xlfn.CONCAT("""",RIGHT(A10,LEN(A10)-7),"""") -> "00 00 00 00 00 00 00 00 7f 01 17 05 00 00 00 00"
A11: 00a0 01 00 02 00 00 00 00 00 00 00 00 00 00 00 00 00 | F11: =_xlfn.CONCAT("""",RIGHT(A11,LEN(A11)-7),"""") -> "01 00 02 00 00 00 00 00 00 00 00 00 00 00 00 00" | K11: 58 | M11: 40 | O11: 75
A12: 00b0 00 00 7f 01 17 06 00 00 00 00 01 00 02 00 00 00 | F12: =_xlfn.CONCAT("""",RIGHT(A12,LEN(A12)-7),"""") -> "00 00 7f 01 17 06 00 00 00 00 01 00 02 00 00 00" | K12: 227 | M12: 262 | O12: 192
A13: 00c0 00 00 00 00 00 00 00 00 00 00 00 00 7f 01 17 07 | F13: =_xlfn.CONCAT("""",RIGHT(A13,LEN(A13)-7),"""") -> "00 00 00 00 00 00 00 00 00 00 00 00 7f 01 17 07" | K13: =K11/100*K12+(100-K11) -> 173.66 | M13: =M11/100*M12+(100-M11) -> 164.8 | O13: =O11/100*O12+(100-O11) -> 169
A14: 00d0 00 00 00 00 01 00 02 00 00 00 00 00 00 00 00 00 | F14: =_xlfn.CONCAT("""",RIGHT(A14,LEN(A14)-7),"""") -> "00 00 00 00 01 00 02 00 00 00 00 00 00 00 00 00"
A15: 00e0 00 00 00 00 00 00 7f 01 17 08 00 00 00 00 01 00 | F15: =_xlfn.CONCAT("""",RIGHT(A15,LEN(A15)-7),"""") -> "00 00 00 00 00 00 7f 01 17 08 00 00 00 00 01 00"
A16: 00f0 02 00 00 00 00 00 00 00 00 00 00 00 00 00 00 00 | F16: =_xlfn.CONCAT("""",RIGHT(A16,LEN(A16)-7),"""") -> "02 00 00 00 00 00 00 00 00 00 00 00 00 00 00 00"
A17: 0100 7f 01 17 09 00 00 00 00 01 00 02 00 00 00 00 00 | F17: =_xlfn.CONCAT("""",RIGHT(A17,LEN(A17)-7),"""") -> "7f 01 17 09 00 00 00 00 01 00 02 00 00 00 00 00"
A18: 0110 00 00 00 00 00 00 00 00 00 00 7f 01 17 0a 00 00 | F18: =_xlfn.CONCAT("""",RIGHT(A18,LEN(A18)-7),"""") -> "00 00 00 00 00 00 00 00 00 00 7f 01 17 0a 00 00"
A19: 0120 00 00 01 00 02 00 00 00 00 00 00 00 00 00 00 00 | F19: =_xlfn.CONCAT("""",RIGHT(A19,LEN(A19)-7),"""") -> "00 00 01 00 02 00 00 00 00 00 00 00 00 00 00 00"
A20: 0130 00 00 00 00 7f 01 17 0b 00 00 00 00 01 00 02 00 | F20: =_xlfn.CONCAT("""",RIGHT(A20,LEN(A20)-7),"""") -> "00 00 00 00 7f 01 17 0b 00 00 00 00 01 00 02 00"
A21: 0140 00 00 00 00 00 00 00 00 00 00 00 00 00 00 7f 01 | F21: =_xlfn.CONCAT("""",RIGHT(A21,LEN(A21)-7),"""") -> "00 00 00 00 00 00 00 00 00 00 00 00 00 00 7f 01"
A22: 0150 17 0c 00 00 00 00 01 00 02 00 00 00 00 00 00 00 | F22: =_xlfn.CONCAT("""",RIGHT(A22,LEN(A22)-7),"""") -> "17 0c 00 00 00 00 01 00 02 00 00 00 00 00 00 00"
A23: 0160 00 00 00 00 00 00 00 00 7f 01 17 0d 00 00 00 00 | F23: =_xlfn.CONCAT("""",RIGHT(A23,LEN(A23)-7),"""") -> "00 00 00 00 00 00 00 00 7f 01 17 0d 00 00 00 00"
A24: 0170 01 00 02 00 00 00 00 00 00 00 00 00 00 00 00 00 | F24: =_xlfn.CONCAT("""",RIGHT(A24,LEN(A24)-7),"""") -> "01 00 02 00 00 00 00 00 00 00 00 00 00 00 00 00"
A25: 0180 00 00 7f 01 17 0e 00 00 00 00 01 00 02 00 00 00 | F25: =_xlfn.CONCAT("""",RIGHT(A25,LEN(A25)-7),"""") -> "00 00 7f 01 17 0e 00 00 00 00 01 00 02 00 00 00"
... A65: 0400 20 20 20 20 23 f7 | F65: =_xlfn.CONCAT("""",RIGHT(A65,LEN(A65)-7),"""") -> "20 20 20 20 23 f7"

Sheet Sheet4
A1: 0 | B1: f0 | C1: 0 | D1: 21 | E1: 24 | F1: 9 | G1: 0 | H1: 6 | I1: 11 | J1: 0 | K1: 0e | L1: 0 | M1: 0 | N1: 0 | O1: 0 | P1: 0 | Q1: 0 | S1: 6=patch dump | U1: 0e=patch number
A2: 10 | B2: 7f | C2: 0 | D2: 3 | E2: 1 | F2: 0e | G2: 0 | H2: 7f | I2: 1 | J2: 17 | K2: 0 | L2: 24 | M2: 7 | N2: 2c | O2: 2f | P2: 1 | Q2: 1 | S2: action 0, 24=utility, 7=bank bg/text colors, colors, 1=press
A3: 20 | B3: 2 | C3: 0 | D3: 0 | E3: 0 | F3: 0 | G3: 0 | H3: 0 | I3: 0 | J3: 0 | K3: 0 | L3: 0 | M3: 0 | N3: 0 | O3: 0 | P3: 0 | Q3: 0
A4: 30 | B4: 7f | C4: 1 | D4: 17 | E4: 1 | F4: 24 | G4: 7 | H4: 36 | I4: 7 | J4: 1 | K4: 2 | L4: 2 | M4: 0 | N4: 0 | O4: 0 | P4: 0 | Q4: 0 | S4: action 1, 24=utility, 7=bank bg/text colors, 2=release
A5: 40 | B5: 0 | C5: 0 | D5: 0 | E5: 0 | F5: 0 | G5: 0 | H5: 0 | I5: 0 | J5: 0 | K5: 0 | L5: 7f | M5: 1 | N5: 17 | O5: 2 | P5: 24 | Q5: 7 | S5: action 2, 24=utility, 7=bank bg/text colors, 3= longpress
A6: 50 | B6: 0 | C6: 7 | D6: 1 | E6: 3 | F6: 2 | G6: 0 | H6: 0 | I6: 0 | J6: 0 | K6: 0 | L6: 0 | M6: 0 | N6: 0 | O6: 0 | P6: 0 | Q6: 0
A7: 60 | B7: 0 | C7: 0 | D7: 0 | E7: 0 | F7: 7f | G7: 1 | H7: 17 | I7: 3 | J7: 0e | K7: 3 | L7: 0 | M7: 0 | N7: 1 | O7: 7 | P7: 2 | Q7: 0 | S7: action 3, 0e=page, 3=page1, 7=longdouble press
A8: 70 | B8: 0 | C8: 0 | D8: 0 | E8: 0 | F8: 0 | G8: 0 | H8: 0 | I8: 0 | J8: 0 | K8: 0 | L8: 0 | M8: 0 | N8: 0 | O8: 0 | P8: 7f | Q8: 1
A9: 80 | B9: 17 | C9: 4 | D9: 0e | E9: 4 | F9: 0 | G9: 0 | H9: 1 | I9: 8 | J9: 2 | K9: 0 | L9: 0 | M9: 0 | N9: 0 | O9: 0 | P9: 0 | Q9: 0 | S9: action 4, 0e=page, 4=page2, 8=longdouble release
A10: 90 | B10: 0 | C10: 0 | D10: 0 | E10: 0 | F10: 0 | G10: 0 | H10: 0 | I10: 0 | J10: 7f | K10: 1 | L10: 17 | M10: 5 | N10: 0 | O10: 0 | P10: 0 | Q10: 0
A11: 00a0 | B11: 1 | C11: 0 | D11: 2 | E11: 0 | F11: 0 | G11: 0 | H11: 0 | I11: 0 | J11: 0 | K11: 0 | L11: 0 | M11: 0 | N11: 0 | O11: 0 | P11: 0 | Q11: 0
A12: 00b0 | B12: 0 | C12: 0 | D12: 7f | E12: 1 | F12: 17 | G12: 6 | H12: 0 | I12: 0 | J12: 0 | K12: 0 | L12: 1 | M12: 0 | N12: 2 | O12: 0 | P12: 0 | Q12: 0
A13: 00c0 | B13: 0 | C13: 0 | D13: 0 | E13: 0 | F13: 0 | G13: 0 | H13: 0 | I13: 0 | J13: 0 | K13: 0 | L13: 0 | M13: 0 | N13: 7f | O13: 1 | P13: 17 | Q13: 7
A14: 00d0 | B14: 0 | C14: 0 | D14: 0 | E14: 0 | F14: 1 | G14: 0 | H14: 2 | I14: 0 | J14: 0 | K14: 0 | L14: 0 | M14: 0 | N14: 0 | O14: 0 | P14: 0 | Q14: 0 | Y14: update preset actions
A15: 0 | B15: 0 | C15: 0 | D15: 0 | E15: 0 | F15: 0 | G15: 0 | H15: 7f | I15: 1 | J15: 17 | K15: 8 | L15: 0 | M15: 0 | N15: 0 | O15: 0 | P15: 1 | Q15: 0 | S15: f0 | T15: 0 | U15: 21 | V15: 24 | W15: 9 | X15: 0 | Y15: 70 | Z15: 4 | AA15: 0e | AB15: 0 | AC15: 1 | AD15: 0 | AE15: 0 | AF15: 0 | AG15: 0
A16: 00f0 | B16: 2 | C16: 0 | D16: 0 | E16: 0 | F16: 0 | G16: 0 | H16: 0 | I16: 0 | J16: 0 | K16: 0 | L16: 0 | M16: 0 | N16: 0 | O16: 0 | P16: 0 | Q16: 0 | AA16: preset | AB16: msg num | AC16: action
A17: 100 | B17: 7f | C17: 1 | D17: 17 | E17: 9 | F17: 0 | G17: 0 | H17: 0 | I17: 0 | J17: 1 | K17: 0 | L17: 2 | M17: 0 | N17: 0 | O17: 0 | P17: 0 | Q17: 0 | S17: header block - 16 bytes + 7f
A18: 110 | B18: 0 | C18: 0 | D18: 0 | E18: 0 | F18: 0 | G18: 0 | H18: 0 | I18: 0 | J18: 0 | K18: 0 | L18: 7f | M18: 1 | N18: 17 | O18: 0a | P18: 0 | Q18: 0 | S18: 5 bytes + 7f
A19: 120 | B19: 0 | C19: 0 | D19: 1 | E19: 0 | F19: 2 | G19: 0 | H19: 0 | I19: 0 | J19: 0 | K19: 0 | L19: 0 | M19: 0 | N19: 0 | O19: 0 | P19: 0 | Q19: 0 | S19: 26 bytes each for the 32 action slots
A20: 130 | B20: 0 | C20: 0 | D20: 0 | E20: 0 | F20: 7f | G20: 1 | H20: 17 | I20: 0b | J20: 0 | K20: 0 | L20: 0 | M20: 0 | N20: 1 | O20: 0 | P20: 2 | Q20: 0 | S20: 01 17 [slot] [6 bytes] [02 + 15x00] 7f
A21: 140 | B21: 0 | C21: 0 | D21: 0 | E21: 0 | F21: 0 | G21: 0 | H21: 0 | I21: 0 | J21: 0 | K21: 0 | L21: 0 | M21: 0 | N21: 0 | O21: 0 | P21: 7f | Q21: 1
A22: 150 | B22: 17 | C22: 0c | D22: 0 | E22: 0 | F22: 0 | G22: 0 | H22: 1 | I22: 0 | J22: 2 | K22: 0 | L22: 0 | M22: 0 | N22: 0 | O22: 0 | P22: 0 | Q22: 0 | S22: 02 20 [32 bytes preset name] 7f
A23: 160 | B23: 0 | C23: 0 | D23: 0 | E23: 0 | F23: 0 | G23: 0 | H23: 0 | I23: 0 | J23: 7f | K23: 1 | L23: 17 | M23: 0d | N23: 0 | O23: 0 | P23: 0 | Q23: 0 | S23: 03 20 [32 bytes toggle name] 7f
A24: 170 | B24: 1 | C24: 0 | D24: 2 | E24: 0 | F24: 0 | G24: 0 | H24: 0 | I24: 0 | J24: 0 | K24: 0 | L24: 0 | M24: 0 | N24: 0 | O24: 0 | P24: 0 | Q24: 0 | S24: 04 20 [32 bytes longname] 7f
A25: 180 | B25: 0 | C25: 0 | D25: 7f | E25: 1 | F25: 17 | G25: 0e | H25: 0 | I25: 0 | J25: 0 | K25: 0 | L25: 1 | M25: 0 | N25: 2 | O25: 0 | P25: 0 | Q25: 0 | S25: 05 20 [31 bytes] 7f
A26: 190 | B26: 0 | C26: 0 | D26: 0 | E26: 0 | F26: 0 | G26: 0 | H26: 0 | I26: 0 | J26: 0 | K26: 0 | L26: 0 | M26: 0 | N26: 7f | O26: 1 | P26: 17 | Q26: 0f | S26: 06 20 [32 bytes shiftname?] 7f
A27: 01a0 | B27: 0 | C27: 0 | D27: 0 | E27: 0 | F27: 1 | G27: 0 | H27: 2 | I27: 0 | J27: 0 | K27: 0 | L27: 0 | M27: 0 | N27: 0 | O27: 0 | P27: 0 | Q27: 0 | S27: checksum
A28: 01b0 | B28: 0 | C28: 0 | D28: 0 | E28: 0 | F28: 0 | G28: 0 | H28: 7f | I28: 1 | J28: 17 | K28: 10 | L28: 0 | M28: 0 | N28: 0 | O28: 0 | P28: 1 | Q28: 0 | S28: f7
A29: 01c0 | B29: 2 | C29: 0 | D29: 0 | E29: 0 | F29: 0 | G29: 0 | H29: 0 | I29: 0 | J29: 0 | K29: 0 | L29: 0 | M29: 0 | N29: 0 | O29: 0 | P29: 0 | Q29: 0
A30: 01d0 | B30: 7f | C30: 1 | D30: 17 | E30: 11 | F30: 0 | G30: 0 | H30: 0 | I30: 0 | J30: 1 | K30: 0 | L30: 2 | M30: 0 | N30: 0 | O30: 0 | P30: 0 | Q30: 0
A31: 1 | B31: 0 | C31: 0 | D31: 0 | E31: 0 | F31: 0 | G31: 0 | H31: 0 | I31: 0 | J31: 0 | K31: 0 | L31: 7f | M31: 1 | N31: 17 | O31: 12 | P31: 0 | Q31: 0
A32: 01f0 | B32: 0 | C32: 0 | D32: 1 | E32: 0 | F32: 2 | G32: 0 | H32: 0 | I32: 0 | J32: 0 | K32: 0 | L32: 0 | M32: 0 | N32: 0 | O32: 0 | P32: 0 | Q32: 0
A33: 200 | B33: 0 | C33: 0 | D33: 0 | E33: 0 | F33: 7f | G33: 1 | H33: 17 | I33: 13 | J33: 0 | K33: 0 | L33: 0 | M33: 0 | N33: 1 | O33: 0 | P33: 2 | Q33: 0
A34: 210 | B34: 0 | C34: 0 | D34: 0 | E34: 0 | F34: 0 | G34: 0 | H34: 0 | I34: 0 | J34: 0 | K34: 0 | L34: 0 | M34: 0 | N34: 0 | O34: 0 | P34: 7f | Q34: 1
A35: 220 | B35: 17 | C35: 14 | D35: 0 | E35: 0 | F35: 0 | G35: 0 | H35: 1 | I35: 0 | J35: 2 | K35: 0 | L35: 0 | M35: 0 | N35: 0 | O35: 0 | P35: 0 | Q35: 0
A36: 230 | B36: 0 | C36: 0 | D36: 0 | E36: 0 | F36: 0 | G36: 0 | H36: 0 | I36: 0 | J36: 7f | K36: 1 | L36: 17 | M36: 15 | N36: 0 | O36: 0 | P36: 0 | Q36: 0
A37: 240 | B37: 1 | C37: 0 | D37: 2 | E37: 0 | F37: 0 | G37: 0 | H37: 0 | I37: 0 | J37: 0 | K37: 0 | L37: 0 | M37: 0 | N37: 0 | O37: 0 | P37: 0 | Q37: 0
A38: 250 | B38: 0 | C38: 0 | D38: 7f | E38: 1 | F38: 17 | G38: 16 | H38: 0 | I38: 0 | J38: 0 | K38: 0 | L38: 1 | M38: 0 | N38: 2 | O38: 0 | P38: 0 | Q38: 0
A39: 260 | B39: 0 | C39: 0 | D39: 0 | E39: 0 | F39: 0 | G39: 0 | H39: 0 | I39: 0 | J39: 0 | K39: 0 | L39: 0 | M39: 0 | N39: 7f | O39: 1 | P39: 17 | Q39: 17
A40: 270 | B40: 0 | C40: 0 | D40: 0 | E40: 0 | F40: 1 | G40: 0 | H40: 2 | I40: 0 | J40: 0 | K40: 0 | L40: 0 | M40: 0 | N40: 0 | O40: 0 | P40: 0 | Q40: 0
...
